from django.contrib.auth import get_user_model
from rest_framework import serializers
from rest_framework.relations import SlugRelatedField
from rest_framework.validators import UniqueTogetherValidator

from posts.models import Comment, Follow, Group, Post

User = get_user_model()


class GroupSerializer(serializers.ModelSerializer):

    class Meta:
        fields = ('id', 'title', 'description', 'slug')
        model = Group


class PostSerializer(serializers.ModelSerializer):
    author = SlugRelatedField(slug_field='username', read_only=True)

    class Meta:
        fields = ('id', 'text', 'pub_date', 'author', 'image', 'group')
        model = Post


class CommentSerializer(serializers.ModelSerializer):
    author = serializers.SlugRelatedField(
        read_only=True, slug_field='username'
    )

    class Meta:
        model = Comment
        fields = ('id', 'author', 'post', 'text', 'created')
        read_only_fields = ('post',)


class FollowSerializer(serializers.ModelSerializer):
    following = serializers.SlugRelatedField(
        slug_field='username',
        queryset=User.objects.all()
    )
    user = serializers.SlugRelatedField(
        slug_field='username',
        read_only=True,
        default=serializers.CurrentUserDefault()
    )

    class Meta:
        fields = ('user', 'following')
        model = Follow
        validators = [
            UniqueTogetherValidator(
                queryset=Follow.objects.all(),
                fields=['user', 'following'],
                message='Вы уже подписаны на этого пользователя'
            )
        ]

    def validate_following(self, value):
        if self.context['request'].user == value:
            raise serializers.ValidationError(
                'Вы не можете подписаться сами на себя'
            )
        return value
